Traceback (most recent call last):
  File "/Library/Frameworks/Python.framework/Versions/3.12/lib/python3.12/site-packages/jupyter_cache/executors/utils.py", line 58, in single_nb_execution
    executenb(
  File "/Library/Frameworks/Python.framework/Versions/3.12/lib/python3.12/site-packages/nbclient/client.py", line 1314, in execute
    return NotebookClient(nb=nb, resources=resources, km=km, **kwargs).execute()
           ^^^^^^^^^^^^^^^^^^^^^^^^^^^^^^^^^^^^^^^^^^^^^^^^^^^^^^^^^^^^^^^^^^^^^
  File "/Library/Frameworks/Python.framework/Versions/3.12/lib/python3.12/site-packages/jupyter_core/utils/__init__.py", line 165, in wrapped
    return loop.run_until_complete(inner)
           ^^^^^^^^^^^^^^^^^^^^^^^^^^^^^^
  File "/Library/Frameworks/Python.framework/Versions/3.12/lib/python3.12/asyncio/base_events.py", line 684, in run_until_complete
    return future.result()
           ^^^^^^^^^^^^^^^
  File "/Library/Frameworks/Python.framework/Versions/3.12/lib/python3.12/site-packages/nbclient/client.py", line 709, in async_execute
    await self.async_execute_cell(
  File "/Library/Frameworks/Python.framework/Versions/3.12/lib/python3.12/site-packages/nbclient/client.py", line 1062, in async_execute_cell
    await self._check_raise_for_error(cell, cell_index, exec_reply)
  File "/Library/Frameworks/Python.framework/Versions/3.12/lib/python3.12/site-packages/nbclient/client.py", line 918, in _check_raise_for_error
    raise CellExecutionError.from_cell_and_msg(cell, exec_reply_content)
nbclient.exceptions.CellExecutionError: An error occurred while executing the following cell:
------------------

system_price = m.getConstrByName(f"energy_balance[{1}]").Pi
------------------


[0;31m---------------------------------------------------------------------------[0m
[0;31mAttributeError[0m                            Traceback (most recent call last)
Cell [0;32mIn[8], line 1[0m
[0;32m----> 1[0m system_price [38;5;241m=[39m [43mm[49m[38;5;241;43m.[39;49m[43mgetConstrByName[49m[43m([49m[38;5;124;43mf[39;49m[38;5;124;43m"[39;49m[38;5;124;43menergy_balance[[39;49m[38;5;132;43;01m{[39;49;00m[38;5;241;43m1[39;49m[38;5;132;43;01m}[39;49;00m[38;5;124;43m][39;49m[38;5;124;43m"[39;49m[43m)[49m[38;5;241;43m.[39;49m[43mPi[49m

File [0;32msrc/gurobipy/constr.pxi:67[0m, in [0;36mgurobipy.Constr.__getattr__[0;34m()[0m

File [0;32msrc/gurobipy/constr.pxi:95[0m, in [0;36mgurobipy.Constr.getAttr[0;34m()[0m

File [0;32msrc/gurobipy/attrutil.pxi:103[0m, in [0;36mgurobipy._getattr[0;34m()[0m

[0;31mAttributeError[0m: Unable to retrieve attribute 'Pi'

